Workbook

Sheet 1 - Assumptions
A1: ECON 134A | ExxonMobil (XOM) DCF Analysis | Assumptions
A3: COMPANY OVERVIEW
A4: Company | B4: ExxonMobil Corporation
A5: Ticker | B5: XOM (NYSE)
A6: Fiscal Year End | B6: December 31
A7: Analysis Date | B7: March 2026
A8: Currency | B8: USD (billions unless noted)
A10: MARKET DATA (AS OF MARCH 2026)
A11: Share Price | B11: 158.81 | D11: Source: Yahoo Finance, March 17, 2026
A12: Shares Outstanding (B) | B12: 4.305 | D12: Source: XOM 10-K FY2025, SEC EDGAR
A13: Market Capitalization ($B) | B13: =B11*B12 -> 683.67705 | D13: Calc: Share Price x Shares Outstanding
A14: 52-Week Range | B14: $95.77 – $126.34 | D14: Source: MarketWatch, March 2026
A16: CAPITAL STRUCTURE
A17: Short-Term Debt ($B) | B17: 9.296 | D17: Source: XOM 10-K FY2025, Balance Sheet
A18: Long-Term Debt ($B) | B18: 34.241 | D18: Source: XOM 10-K FY2025, Balance Sheet
A19: Total Debt ($B) | B19: =B17+B18 -> 43.537 | D19: Source: XOM 10-K FY2025, Balance Sheet
A20: Cash & Cash Equivalents ($B) | B20: 10.681 | D20: Source: XOM 10-K FY2025, Balance Sheet
A21: Net Debt ($B) | B21: =B19-B20 -> 32.856 | D21: Calc: Total Debt minus Cash
A22: Interest Expense ($B) | B22: 0.603 | D22: Source: XOM 10-K FY2025, Income Statement
A24: WACC INPUTS
A25: Risk-Free Rate (10Y UST Yield) | B25: 0.0431 | D25: Source: US Treasury, March 2026
A26: Beta (5-Year Monthly vs S&P 500) | B26: 0.35 | D26: Source: Yahoo Finance, March 2026. Lower beta reflects oil as inflation hedge
A27: Equity Risk Premium | B27: 0.0446 | D27: Source: Damodaran (NYU Stern), January 2026
A28: Cost of Equity — Low (CAPM) | B28: =B25+B26*B27 -> 0.05871 | D28: Calc: Rf + Beta x ERP = 4.31% + 0.35 x 4.46% = Low estimate. Source: Damodaran implied ERP Jan 2026
A29: Cost of Equity — High (CAPM) | B29: =B25+B26*0.055 -> 0.06235 | D29: Calc: Rf + Beta x ERP_high = 4.31% + 0.84 x 6%. Source: investing.com
A30: Cost of Equity — Average (used in WACC) | B30: =(B28+B29)/2 -> 0.06053 | D30: Average of Low (Damodaran) and High (investing.com)
A31: Cost of Debt (pre-tax) | B31: =B22/B19 -> 0.013850288 | D31: Source: XOM 10-K FY2024, Income Statement / Balance Sheet
A32: Effective Tax Rate (3-yr avg) | B32: =B55 -> 0.27876321 | D32: Formula: =AVERAGE of (Income Tax Exp / EBT) for FY2022-FY2024. See derivation table below. Source: XOM 10-K FY2022, FY2023, FY2024
A33: After-Tax Cost of Debt | B33: =B31*(1-B32) -> 0.0099893375 | D33: Calc: Pre-Tax Cost of Debt x (1 minus Tax Rate)
A34: Weight of Equity (Mkt Value) | B34: =B13/(B13+B19) -> 0.94013179 | D34: Calc: Market Cap divided by (Market Cap + Total Debt)
A35: Weight of Debt | B35: =1-B34 -> 0.059868205 | D35: Calc: 1 minus Weight of Equity
A36: WACC | B36: =B34*B30+B35*B33 -> 0.057504221 | D36: Calc: We x Ke_midpoint + Wd x Kd_after_tax
A38: FCF GROWTH RATE — ANALYST REASONING
A39: ANALYST NOTE: We do NOT use average of the past 5 years of FCF. The 2021 FCF reflects COVID demand destruction (Brent avg $70 → $42 in 2020). The 2022 FCF reflects a one-time Russia/Ukraine supply shock (Brent avg $100). And A normalized FCF uses a mid-cycle oil price of $70–75/bbl. We also add ~$3B/yr in Pioneer acquisition synergies (cost savings + Permian volume uplift) phasing in over FY2025–2027. FCF growth of 5% is conservative relative to the 7–9% production CAGR XOM has guided for through 2030, reflecting execution risk and our $72/bbl base-case oil price.
A41: Base-Case FCF (FY2024 normalized, $B) | B41: 36.1 | D41: Source: XOM 10-K FY2025.
A42: FCF Growth Rate — Years 1 | B42: 0.23695291 | D42: Derived: avg of (C7-E7)/C7 and (C7-F7)/C7 = avg(11.02%, 36.37%) = 23.70%. C7=FY2022 Russia shock peak ($36.1B), E7=FY2024 ($32.1B), F7=FY2025 ($23.0B). Sources: XOM 10-K FY2022, FY2024, FY2025.
A43: FCF Growth Rate — Years 2-5 | B43: -0.1 | D43: Used recent trend of FCFs after past Russian shock and averaged them with cyclical trends in mind.
A44: Terminal Growth Rate | B44: 0.025 | D44: Source: WallStreetPrep (2.0–3.5% range for large-cap energy). 2.5% reflects long-run nominal GDP growth, offset by energy-transition headwinds.
A45: Base-Case Oil Price ($/bbl, Brent) | B45: 72 | D45: Source: EIA Short-Term Energy Outlook, March 2026. Mid-cycle assumption.
A47: Yellow cells = key assumptions (change to run scenarios)
...

Sheet 2 - Calculations
A1: ECON 134A | ExxonMobil (XOM) DCF Analysis | Calculations
A3: SECTION 1: HISTORICAL FREE CASH FLOW ANALYSIS ($B)
B4: FY2021 | C4: FY2022 | D4: FY2023 | E4: FY2024 | F4: FY2025
A5: Operating Cash Flow ($B) | B5: 28.4 | C5: 59 | D5: 55.4 | E5: 55.022 | F5: 51.97 | G5: Source: XOM 10-K / MacroTrends.net — FCF = OCF - Net Capex
A6: Capital Expenditures ($B) | B6: 20.3 | C6: 22.9 | D6: 19.3 | E6: 22.9 | F6: 29
A7: Free Cash Flow ($B) | B7: =B5-B6 -> 8.1 | C7: =C5-C6 -> 36.1 | D7: =D5-D6 -> 36.1 | E7: =E5-E6 -> 32.122 | F7: =F5-F6 -> 22.97
A8: Brent Crude Avg ($/bbl) | B8: 70.9 | C8: 100.9 | D8: 82.6 | E8: 80 | F8: 70
A9: Adjusted FCF Notes | B9: Low: commodity cycle trough | C9: High: Russia/Ukraine shock | D9: Normalizing | E9: Normalized base | F9: Low: commodity cycle trough
A10: YoY FCF Growth (%) | B10: n/a | C10: =(C7-B7)/ABS(B7) -> 3.4567901 | D10: =(D7-C7)/ABS(C7) -> 0 | E10: =(E7-D7)/ABS(D7) -> -0.11019391 | F10: =(F7-E7)/ABS(E7) -> -0.28491377
A11: 5-Year Simple Average FCF ($B) | B11: =AVERAGE(B7:F7) -> 27.0784
A13: FCF Normalization: 5-year simple average ($B) = $27.1B — NOT used as base. Instead, FY2022 $36.1B is used as it best reflects current cost structure and events (Iran War). However future FCFs should be estimated to normalize to 2023 and 2024 numbers, hence the negativity.
A15: SECTION 2: 5-YEAR DCF PROJECTION
B16: Year 1 (FY2025) | C16: Year 2 (FY2026) | D16: Year 3 (FY2027) | E16: Year 4 (FY2028) | F16: Year 5 (FY2029) | H16: Notes
A17: FCF Growth Rate (%) | B17: 0.23695291 | C17: ='1 - Assumptions'!$B$43 -> -0.1 | D17: ='1 - Assumptions'!$B$43 -> -0.1 | E17: ='1 - Assumptions'!$B$43 -> -0.1 | F17: ='1 - Assumptions'!$B$43 -> -0.1 | H17: Links to Assumptions!B41
A18: Projected FCF ($B) | B18: 44.654 | C18: 40.1886 | D18: 36.16974 | E18: 32.552766 | F18: 29.297489 | H18: Base × (1 + growth rate)^n
A19: Discount Factor [1/(1+WACC)^t] | B19: 0.9456227 | C19: 0.8942023 | D19: 0.84557799 | E19: 0.79959775 | F19: 0.75611778 | H19: WACC from Assumptions!B34
A20: Present Value of FCF ($B) | B20: 42.225836 | C20: 35.936738 | D20: 30.584336 | E20: 26.029118 | F20: 22.152353 | H20: Source: = Projected FCF × Discount Factor
A21: Sum of PV (FCF) ($B) | B21: 156.92838
A23: SECTION 3: TERMINAL VALUE CALCULATION
A24: Terminal FCF (Year 5 × (1+TGR)) ($B) | B24: 30.029927
A25: Terminal Value (Gordon Growth) ($B) | B25: 923.87775 | D25: Source: Discount TV back 5 years at WACC
A26: PV of Terminal Value ($B) | B26: 698.56039
A28: SECTION 4: ENTERPRISE VALUE → EQUITY VALUE → INTRINSIC PRICE
A29: Enterprise Value ($B) | B29: 855.48877 | D29: Calc: Sum of PV(FCF) + PV(Terminal Value)
A30: Less: Net Debt ($B) | B30: ='1 - Assumptions'!B21 -> 32.856 | D30: Links to Assumptions!B22
A31: Equity Value ($B) | B31: 822.63277
A32: Shares Outstanding (B) | B32: ='1 - Assumptions'!B12 -> 4.305
A33: INTRINSIC SHARE PRICE | B33: 191.08775
A34: Current Market Price | B34: ='1 - Assumptions'!B11 -> 158.81
A35: Upside / (Downside) | B35: 0.20324761

Sheet 3 - Scenario Analysis
A1: ECON 134A | ExxonMobil (XOM) | Scenario & Sensitivity Analysis
A3: SCENARIO ANALYSIS — BEAR / BASE / BULL
A4: Assumption | B4: Bear Case | C4: Base Case | D4: Bull Case | F4: Bear | G4: Bull
A5: Oil Price ($/bbl, Brent) | B5: 50 | C5: 72 | D5: 95
A6: FCF Growth Rate (Yrs 1–5) | B6: -0.15 | C6: 0.05 | D6: 0.3
A7: Terminal Growth Rate | B7: 0.01 | C7: 0.025 | D7: 0.035
A8: WACC | B8: 0.135 | C8: ='1 - Assumptions'!B36 -> 0.057504221 | D8: 0.08
A9: Normalized Base FCF ($B) | B9: ='2 - Calculations'!B7 -> 8.1 | C9: ='2 - Calculations'!E7 -> 32.122 | D9: ='2 - Calculations'!C7 -> 36.1
A10: Probability Weight | B10: 0.25 | C10: 0.5 | D10: 0.25
A12: DERIVED INTRINSIC PRICES
A13: Intrinsic Share Price | B13: 0.24 | C13: 255.95 | D13: 555.4 | F13: Calculated via full DCF at scenario assumptions (see Calculations tab)
B14: -0.99849563 | C14: 0.61169696 | D14: 2.4972724
A15: Probability-Weighted Intrinsic Value | B15: 266.89
A16: Market Price | B16: 158.81
A17: SCENARIO DISCUSSION
A18: The base case (50% probability) is the most likely outcome. It assumes stable oil prices around $72/bbl — consistent with the EIA's March 2026 Short-Term Energy Outlook — modest FCF growth of 5%, and a WACC of 5.75%, yielding an intrinsic value of $255.95. The bear case (25% probability) reflects a severe demand contraction driven by accelerated energy transition adoption and a global recession, compressing FCF growth to -15% annually from an already-depressed FY2025 base of $8.1B and pushing WACC to 13.5% as investors reprice energy sector risk. Under these conditions equity value is nearly fully consumed by net debt ($32.9B), producing a near-zero intrinsic price — a tail risk but not implausible given XOM's leverage at depressed earnings. The bull case (25% probability) assumes a sustained Iran-related supply shock driving Brent above $95/bbl, with FCF growth of 30% from the FY2022 Russia-shock peak base of $36.1B and a lower WACC of 8.0% reflecting renewed energy sector appetite, yielding $555.40. The probability-weighted intrinsic value of $266.89 implies significant upside to the current market price of $158.81 even after accounting for downside tail risk. Sources: EIA STEO March 2026; Damodaran ERP January 2026; XOM 10-K FY2025.
A22: SENSITIVITY TABLE — INTRINSIC PRICE ($) BY WACC × TERMINAL GROWTH RATE
A23: WACC \ TGR → | B23: 0.01 | C23: 0.015 | D23: 0.02 | E23: 0.025 | F23: 0.03 | G23: 0.035
A24: 0.04 | B24: 294.28 | C24: 348.55 | D24: 429.96 | E24: 565.63 | F24: 836.97 | G24: 1651.01
A25: 0.05 | B25: 218.08 | C25: 246.06 | D25: 283.37 | E25: 335.6 | F25: 413.95 | G25: 544.52
A26: 0.057 | B26: 184.05 | C26: 203.37 | D26: 227.92 | E26: 260.13 | F26: 304.28 | G26: 368.5
A27: 0.06 | B27: 172.38 | C27: 189.14 | D27: 210.1 | E27: 237.04 | F27: 272.96 | G27: 323.24
A28: 0.07 | B28: 141.93 | C28: 152.94 | D28: 166.15 | E28: 182.29 | F28: 202.47 | G28: 228.42
A29: 0.08 | B29: 120.19 | C29: 127.89 | D29: 136.86 | E29: 147.47 | F29: 160.19 | G29: 175.75
A30: 0.09 | B30: 103.9 | C30: 109.53 | D30: 115.95 | E30: 123.36 | F30: 132.01 | G30: 142.24
A31: 0.1 | B31: 91.24 | C31: 95.5 | D31: 100.28 | E31: 105.7 | F31: 111.89 | G31: 119.04
A32: 0.11 | B32: 81.12 | C32: 84.43 | D32: 88.09 | E32: 92.19 | F32: 96.81 | G32: 102.03
A34: Green = above market ($158.81). Red = below. Yellow = base case (WACC 5.75%, TGR 2.5%). FCF growth fixed at 5%, base FCF $32.122B.
A35: SENSITIVITY ANALYSIS — KEY FINDINGS
A36: The sensitivity analysis reveals that WACC is by far the most powerful driver of intrinsic value in this model. Moving WACC from the base case of 5.75% up to just 8% reduces the intrinsic price from $227.92 to $136.86 — a 40% swing — holding all else constant. This is a direct consequence of XOM's large terminal value ($698.6B, or ~82% of enterprise value): because the Gordon Growth model applies the discount rate in perpetuity, even small changes in WACC compound dramatically. The terminal growth rate is the second most sensitive variable; at a fixed WACC of 5.75%, moving TGR from 1.0% to 3.5% adds roughly $170 to the intrinsic price. FCF growth rate in Years 1-5 has the least impact by comparison, since those cash flows represent only ~18% of total enterprise value. This asymmetry underscores a key limitation of DCF for mature energy companies: the valuation is highly sensitive to long-run assumptions (WACC and TGR) that are inherently difficult to forecast, meaning the model output should be treated as a range rather than a point estimate.

Sheet 4 - Summary
A1: ECON 134A | ExxonMobil (XOM) | Executive Summary
A3: INVESTMENT THESIS
A4: MEMORANDUM
A5: TO: | B5: Professor — ECON 134A
A6: FROM: | B6: Joseph Wallace
A7: DATE: | B7: March 17, 2026
A8: RE: | B8: ExxonMobil (XOM) DCF Valuation — Key Assumptions & Findings
A10: KEY ASSUMPTIONS & RATIONALE
A11: WACC (5.75%): XOM's cost of capital reflects its unusually low beta of 0.35 (Yahoo Finance, March 2026), which captures the company's role as an inflation hedge — oil stocks historically outperform during inflationary periods that depress broader equity markets. Combined with Damodaran's January 2026 implied US ERP of 4.46%, this yields a Cost of Equity midpoint of 6.05% (low: 5.87% using Damodaran ERP; high: 6.24% using investing.com's 6.0% figure). The after-tax Cost of Debt is just 1.0%, reflecting XOM's investment-grade balance sheet and low effective interest rate of 1.4% on $43.5B of total debt. The resulting WACC of 5.75% is low relative to historical energy sector averages, but is defensible given the beta data and current risk-free rate of 4.31% (10-Year UST, March 2026). FCF Growth Rate (Year 1: +23.70%, Years 2–5: −10%/yr): Rather than mechanically extrapolating past FCF, Year 1 growth was derived analytically. The Russia/Ukraine supply shock of FY2022 produced a FCF peak of $36.1B. The percentage deviation of both FY2024 ($32.1B) and FY2025 ($23.0B) from that peak — computed as (FY2022−FY2024)/FY2022 = 11.02% and (FY2022−FY2025)/FY2022 = 36.37% — were averaged to yield 23.70%. This figure proxies the expected FCF recovery from the current Iran-related supply disruption, anchored to a comparable historical shock. Years 2–5 apply −10%/yr mean reversion, consistent with the observed post-Russia-shock FCF decline (FY2022→FY2025: approx. −10%/yr CAGR). Terminal Growth Rate (2.5%): Per WallStreetPrep guidance for large-cap energy companies (range: 2.0%–3.5%), 2.5% was selected as the midpoint, aligning with IMF long-run nominal US GDP growth forecasts. A higher rate was not used given the structural headwinds facing fossil fuel producers from the global energy transition.
A12: INTRINSIC PRICE vs. MARKET PRICE
A13: The base-case DCF yields an intrinsic share price of $191.09 versus XOM's current market price of $158.81 (Yahoo Finance, March 17, 2026), implying a +20.3% discount to fair value. The probability-weighted intrinsic value across Bear, Base, and Bull scenarios is $266.89, though this is heavily influenced by the bull case ($555.40) which reflects an extreme supply shock scenario. Even anchoring conservatively to the base case alone, the stock appears meaningfully undervalued.
A14: WHAT EXPLAINS THE DISCREPANCY?
A15: Several factors likely explain why the market is pricing XOM below our intrinsic estimate. First, the market may be applying a higher implicit WACC than our model — if investors demand a 7–8% cost of equity (reflecting greater energy transition risk), the sensitivity table shows intrinsic value falls to $127–$137, much closer to the current price. Second, our Year 1 FCF growth assumption of +23.70% is contingent on the Iran supply disruption materializing at the scale of the Russia/Ukraine shock, which is not guaranteed — the market may be assigning lower probability to this outcome. Third, XOM's capital expenditure has risen sharply ($29.0B in FY2025 vs. $19.3B in FY2023), which compresses near-term free cash flow and may be causing the market to apply a lower near-term FCF multiple. Finally, structural ESG-driven divestment from fossil fuel stocks continues to weigh on energy sector valuations independent of fundamentals, creating a persistent discount that DCF models do not capture. In aggregate, the model suggests XOM is undervalued, but the margin of safety is sensitive to WACC and Year 1 FCF assumptions.
A26: ExxonMobil (XOM) appears undervalued at its current market price of $158.81. Our base-case DCF yields an intrinsic share price of $191.09, implying +20.3% upside. The model applies a WACC of 5.75%, reflecting XOM's low beta of 0.35 (Yahoo Finance, March 2026) and Damodaran's January 2026 implied ERP of 4.46%. Year 1 FCF growth of 23.70% is derived from historical shock analysis: the average of (FY2022 peak − FY2024) / FY2022 and (FY2022 peak − FY2025) / FY2022, reflecting the magnitude of the Iran-related supply disruption relative to the Russia/Ukraine shock. Years 2–5 apply −10%/yr mean reversion, consistent with XOM's post-shock FCF trajectory. Terminal growth of 2.5% aligns with long-run nominal GDP expectations (WallStreetPrep). Key upside: Permian Basin growth and Pioneer synergies. Key risks: energy transition pressure and oil normalization below $60/bbl. Probability-weighted intrinsic value: $266.89 (25% Bear / 50% Base / 25% Bull). VERDICT: Overweight, $191 price target.
A28: KEY OUTPUT SUMMARY
A29: WACC | B29: 0.057504221 | C29: Ke (mid) = 8.19%, Kd (after-tax) = 2.62%, We = 93.3%, Wd = 6.7%
A30: Sum of PV (FCF) | B30: 156.928 | C30: Year 1: 23.70% (derived from shock analysis), Years 2–5: −10%/yr
A31: PV of Terminal Value | B31: 698.56 | C31: =CONCATENATE("Approx. ",TEXT('2 - Calculations'!B26/('2 - Calculations'!B29)*100,"0.0"),"% of Enterprise Value") -> Approx. 81.7% of Enterprise Value
A32: Enterprise Value | B32: 855.489 | C32: Sum of PV(FCF) + PV(Terminal Value)
A33: Net Debt | B33: 32.856 | C33: Total Debt $33.0B – Cash $18.2B
A34: Equity Value | B34: 822.633 | C34: Enterprise Value minus Net Debt
A35: Intrinsic Share Price | B35: 191.09 | C35: BASE CASE — Equity Value / Shares Outstanding
A36: Current Market Price | B36: 158.81 | C36: NYSE: XOM as of March 2026 (MarketWatch)
A37: Upside / (Downside) | B37: 0.2032 | C37: Intrinsic Price vs. Current Market Price
A38: Prob.-Weighted Value | B38: 266.89 | C38: 0.25 × Bear ($0.24) + 0.50 × Base ($255.95) + 0.25 × Bull ($555.40)
A41: SOURCES
A42: • XOM 10-K FY2025 — SEC EDGAR (Balance Sheet, Income Statement, Cash Flow Statement)
A43: • MarketWatch — Share price, shares outstanding, beta (March 2026)
A44: • US Treasury — 10-Year yield, March 2026 (4.31%)
A45: • Damodaran (NYU Stern) — US Equity Risk Premium, January 2026 update (5.0%)
A46: • EIA Short-Term Energy Outlook — March 2026 Brent crude forecast ($72/bbl base)
A47: • WallStreetPrep — Terminal growth rate guidance for large-cap energy (2.0–3.5%)
A48: • ExxonMobil Investor Day 2024 — Production growth guidance, Pioneer synergy targets
A49: • Seeking Alpha / Bloomberg consensus — Analyst FCF estimates for FY2025–FY2026
